<?xml version="1.0"?>
<robot name="segway_bot"
       xmlns:sensor="http://playerstage.sourceforge.net/gazebo/xmlschema/#sensor" 
       xmlns:controller="http://playerstage.sourceforge.net/gazebo/xmlschema/#controller"
       xmlns:xacro="http://ros.org/wiki/fixme"
       xmlns:interface="http://playerstage.sourceforge.net/gazebo/xmlschema/#interface">>  

<!-- JOINT LIMIT VALUES FOR EFFORT AND VELOCITY NEED TO BE ADDED FOR REVOLUTE AND CONTINUOUS JOINTS -->

  <material name="Blue">
    <color rgba="0.0 0.0 0.8 1.0"/>
  </material>
  <material name="Green">
    <color rgba="0.0 0.8 0.0 1.0"/>
  </material>
  <material name="Red">
    <color rgba="0.8 0.0 0.0 1.0"/>
  </material>
  <material name="White">
    <color rgba="0.0 0.0 0.0 1.0"/>
  </material>

  <!-- base_footprint is a fictitious link(frame) that is on the ground right below base_link origin,
       navigation stack dedpends on this frame -->
  <link name="base_footprint">
    <inertial>
      <mass value="0.000001" />
      <origin xyz="0 0 0" />
      <inertia ixx="0.01" ixy="0.0" ixz="0.0"
               iyy="0.01" iyz="0.0" izz="0.01" />
    </inertial>
    <visual>
      <origin xyz="0 0 0" rpy="0 0 0" />
      <geometry>
        <box size="0.0 0.0 0.0" />
      </geometry>
      
      <material name="Green" />
    </visual>
    <collision>
      <!-- represent base collision with a simple rectangular model, positioned by base_size_z s.t. top
           surface of the collision box matches the top surface of the PR2 base -->
      <origin xyz="0 0 0" rpy="0 0 0" />
      <geometry>
        <box size="0.00 0.00 0.00" />
      </geometry>
    </collision>
  </link>

  <link name="base_link">        
    <inertial>
      <origin xyz="0 -0.3 0" rpy="0 0 0" />
      <mass value="90.72"/>
      <inertia ixx="1.2285"  ixy="0"  ixz="0" iyy="1.961064" iyz="0" izz="1.337364" />
    </inertial>

    <visual>
      <origin xyz="0 0 0" rpy="0 0 0" />
      <geometry name="segway_base_geom">
        <mesh filename="package://segway_robot/meshes/segway_base.stl" />
      </geometry>
      <material name="Blue" />
    </visual>    

    <collision>
      <origin xyz="0 0 0" rpy="0 0 0" />
      <geometry name="segway_base_collision_geom">
      <mesh filename="package://segway_robot/meshes/convex/segway_base_convex.stlb" />
      </geometry>
    </collision>

  </link>

  <link name="segway_left_wheel">        
    <inertial>
      <origin xyz="0 0 0" rpy="0 0 0" />
      <mass value="3.87"/>
      <inertia ixx="0.0852"  ixy="0"  ixz="0" iyy="0.0852" iyz="0" izz="0.1654" />
    </inertial>

    <visual>
      <origin xyz="0 0 0" rpy="0 0 0" />
      <geometry name="segway_left_wheel_geom">
        <mesh filename="package://segway_robot/meshes/segway_wheel.stl" />
      </geometry>
      <material name="Red" />
    </visual>    

    <collision>
      <origin xyz="0 0 0" rpy="0 0 0" />
      <geometry name="segway_left_wheel_collision_geom">
      <cylinder radius="0.24" length="0.09"/>
      </geometry>
    </collision>

  </link>

  <link name="segway_right_wheel">        
    <inertial>
      <origin xyz="0 0 0" rpy="0 0 0" />
      <mass value="3.87"/>
      <inertia ixx="0.0852"  ixy="0"  ixz="0" iyy="0.0852" iyz="0" izz="0.1654" />
    </inertial>

    <visual>
      <origin xyz="0 0 0" rpy="0 0 0" />
      <geometry name="segway_right_wheel_geom">
        <mesh filename="package://segway_robot/meshes/segway_wheel.stl" />
      </geometry>
      <material name="Red" />
    </visual>    

    <collision>
      <origin xyz="0 0 0" rpy="0 0 0" />
      <geometry name="segway_right_wheel_collision_geom">
      <cylinder radius="0.24" length="0.09"/>
      </geometry>
    </collision>

  </link>

  <link name="segway_trailer">
    <inertial>
      <origin xyz="0.15 0.075 0" rpy="0 0 0" />
      <mass value="34.54"/>
      <inertia ixx="0.288"  ixy="0"  ixz="0" iyy="0.547" iyz="0" izz="0.446" />
    </inertial>

    <visual>
      <origin xyz="0 0 0" rpy="0 0 0" />
      <geometry name="segway_trailer-geom">	  
          <mesh filename="package://segway_robot/meshes/trailer.stl" />
      </geometry>
      <material name="Green" />
    </visual>

    <collision>
      <origin xyz="0 0 0" rpy="0 0 0" />
      <geometry name="segway_trailer_collision_geom">
        <mesh filename="package://segway_robot/meshes/convex/trailer_convex.stlb" />
      </geometry>
    </collision>

  </link>

  <link name="segway_trailer_wheel_caster">
    <inertial>
      <origin xyz="0 0 0" rpy="0 0 0" />
      <mass value="1.2"/>
      <inertia ixx="0.01"  ixy="0"  ixz="0" iyy="0.01" iyz="0" izz="0.01" />
    </inertial>

    <visual>
      <origin xyz="0 0 0" rpy="0 0 0" />
      <geometry name="segway_trailer_wheel_caster-geom">	  
          <mesh filename="package://segway_robot/meshes/trailer_wheel_caster.stl" />
      </geometry>
      <material name="Blue" />
    </visual>

    <collision>
      <origin xyz="0 0 0" rpy="0 0 0" />
      <geometry name="segway_trailer_wheel_caster_collision_geom">
        <mesh filename="package://segway_robot/meshes/convex/trailer_wheel_caster_convex.stlb" />
      </geometry>
    </collision>

  </link>

  <link name="segway_trailer_wheel">
    <inertial>
      <origin xyz="0 0 0" rpy="0 0 0" />
      <mass value="2.5"/>
      <inertia ixx="0.042"  ixy="0"  ixz="0" iyy="0.042" iyz="0" izz="0.082" />
    </inertial>

    <visual>
      <origin xyz="0 0 0" rpy="0 0 0" />
      <geometry name="segway_trailer_wheel-geom">	  
          <mesh filename="package://segway_robot/meshes/trailer_wheel.stl" />
      </geometry>
      <material name="Red" />
    </visual>

    <collision>
      <origin xyz="0 0 0" rpy="0 0 0" />
      <geometry name="segway_trailer_wheel_collision_geom">
        <!-- <mesh filename="package://segway_robot/meshes/convex/trailer_wheel_convex.stlb" /> -->
        <cylinder radius="0.127" length="0.08"/>
      </geometry>
    </collision>

  </link>

  <link name="battery_one">        
    <inertial>
      <origin xyz="0 0 0" rpy="0 0 0" />
      <mass value="22.68"/>
      <inertia ixx="0.201"  ixy="0"  ixz="0" iyy="0.263" iyz="0" izz="0.182" />
    </inertial>

    <visual>
      <origin xyz="0 0 0" rpy="0 0 0" />
      <geometry name="battery_one_geom">
        <mesh filename="package://segway_robot/meshes/battery_one.stl" />
      </geometry>
      <material name="Red" />
    </visual>    

    <collision>
      <origin xyz="0 0 0" rpy="0 0 0" />
      <geometry name="battery_one_collision_geom">
      <mesh filename="package://segway_robot/meshes/convex/battery_one_convex.stlb" />
      </geometry>
    </collision>

  </link>

  <link name="battery_two">        
    <inertial>
      <origin xyz="0 0 0" rpy="0 0 0" />
      <mass value="22.68"/>
      <inertia ixx="0.201"  ixy="0"  ixz="0" iyy="0.263" iyz="0" izz="0.182" />
    </inertial>

    <visual>
      <origin xyz="0 0 0" rpy="0 0 0" />
      <geometry name="battery_two_geom">
        <mesh filename="package://segway_robot/meshes/battery_two.stl" />
      </geometry>
      <material name="Red" />
    </visual>    

    <collision>
      <origin xyz="0 0 0" rpy="0 0 0" />
      <geometry name="battery_two_collision_geom">
      <mesh filename="package://segway_robot/meshes/convex/battery_two_convex.stlb" />
      </geometry>
    </collision>

  </link>

  <link name="computer">        
    <inertial>
      <origin xyz="0 0 0" rpy="0 0 0" />
      <mass value="4.54"/>
      <inertia ixx="0.063"  ixy="0"  ixz="0" iyy="0.136" iyz="0" izz="0.103" />
    </inertial>

    <visual>
      <origin xyz="0 0 0" rpy="0 0 0" />
      <geometry name="computer_geom">
        <mesh filename="package://segway_robot/meshes/computer.stl" />
      </geometry>
      <material name="Green" />
    </visual>    

    <collision>
      <origin xyz="0 0 0" rpy="0 0 0" />
      <geometry name="segway_base_collision_geom">
      <mesh filename="package://segway_robot/meshes/convex/computer_convex.stlb" />
      </geometry>
    </collision>

  </link>


  <link name="segway_laser_bracket">
    <inertial>
      <origin xyz="0 0 0" rpy="0 0 0" />
      <mass value="2.27"/>
      <inertia ixx="0.01"  ixy="0"  ixz="0" iyy="0.01" iyz="0" izz="0.01" />
    </inertial>

    <visual>
      <origin xyz="0 0 0" rpy="0 0 0" />
      <geometry name="segway_laser_bracket-geom">
          <mesh filename="package://segway_robot/meshes/laser_bracket.stl" />
      </geometry>
      <material name="Red" />
    </visual>

    <collision>
      <origin xyz="0 0 0" rpy="0 0 0" />
      <geometry name="segway_laser_bracket_collision_geom">
      <mesh filename="package://segway_robot/meshes/convex/laser_bracket_convex.stlb" />
      </geometry>
    </collision>

  </link>

  <link name="R283_hokuyo_laser1">
    <inertial>
      <origin xyz="-0.025 -0.017 0" rpy="0 0 0" />
      <mass value="0.37"/>
      <inertia ixx="0.0004"  ixy="0"  ixz="0" iyy="0.0004" iyz="0" izz="0.0004" />
    </inertial>

    <visual>
      <origin xyz="0 0 0" rpy="0 0 0" />
      <geometry name="R283_hokuyo_laser1-geom">
          <mesh filename="package://segway_robot/meshes/R283_hokuyo_laser1.stl" />
      </geometry>
      <material name="Blue" />
    </visual>

    <collision>
      <origin xyz="0 0 0" rpy="0 0 0" />
      <geometry name="R283_hokuyo_laser1_collision_geom">
      <mesh filename="package://segway_robot/meshes/convex/R283_hokuyo_laser1_convex.stlb" />
      </geometry>
    </collision>

  </link>

  <link name="R313_hokuyo_laser2">
    <inertial>
      <origin xyz="-0.023 0 0" rpy="0 0 0" />
      <mass value="0.37"/>
      <inertia ixx="0.0004"  ixy="0"  ixz="0" iyy="0.0004" iyz="0" izz="0.0004" />
    </inertial>

    <visual>
      <origin xyz="0 0 0" rpy="0 0 0" />
      <geometry name="R313_hokuyo_laser2-geom">
          <mesh filename="package://segway_robot/meshes/R313_hokuyo_laser2.stl" />
      </geometry>
      <material name="Blue" />
    </visual>

    <collision>
      <origin xyz="0 0 0" rpy="0 0 0" />
      <geometry name="R283_hokuyo_laser1_collision_geom">
      <mesh filename="package://segway_robot/meshes/convex/R313_hokuyo_laser2_convex.stlb" />
      </geometry>
    </collision>

  </link>

  <joint name="base_footprint_joint" type="fixed">
    <origin xyz="0 0 0.55" rpy="1.57 0 3.14" />
    <child link="base_link" />
    <parent link="base_footprint"/>
  </joint>
  
  <joint name="segway_left_wheel_joint" type="continuous" >
    <origin xyz="-0.031 -0.353 0.272" rpy="0 0 0"/>
    <axis xyz="0 0 1"/>
    <limit effort="122" velocity="500"/>
    <parent link="base_link" />
    <child link="segway_left_wheel" />
    <calibration reference_position="0.0"/>
  </joint>

  <joint name="segway_right_wheel_joint" type="continuous" >
    <origin xyz="-0.031 -0.353 -0.272" rpy="0 3.14 0"/>    
    <axis xyz="0 0 1"/>
    <limit effort="122" velocity="500"/>
    <parent link="base_link" />
    <child link="segway_right_wheel" />
    <calibration reference_position="0.0"/>
  </joint>

  <joint name="segway_trailer_joint" type="fixed">    
    <origin xyz="0.162 -0.233 0.002" rpy="0 0 0" />
    <parent link="base_link" />
    <child link="segway_trailer" />
    <calibration reference_position="0.0"/>
  </joint>

  <joint name="segway_trailer_wheel_caster_joint" type="continuous">    
    <origin xyz="0.244 -0.038 0.002" rpy="0 0 0" />
    <axis xyz="0 1 0"/>
    <parent link="segway_trailer" />
    <child link="segway_trailer_wheel_caster" />
    <calibration reference_position="0.0"/>
  </joint>

  <joint name="segway_trailer_wheel_joint" type="continuous">    
    <origin xyz="0.076 -0.187 0.002" rpy="0 0 0" />
    <axis xyz="0 0 1"/>
    <parent link="segway_trailer_wheel_caster" />
    <child link="segway_trailer_wheel" />
    <calibration reference_position="0.0"/>
  </joint>

  <joint name="battery_one_joint" type="fixed">    
    <origin xyz="-0.037 -0.231 0" rpy="0 0 0" />
    <parent link="base_link" />
    <child link="battery_one" />
    <calibration reference_position="0.0"/>
  </joint>

  <joint name="battery_two_joint" type="fixed">    
    <origin xyz="0.171 0.074 0" rpy="0 0 0" />
    <parent link="segway_trailer" />
    <child link="battery_two" />
    <calibration reference_position="0.0"/>
  </joint>

  <joint name="computer_joint" type="fixed">    
    <origin xyz="-0.033 0.025 0" rpy="0 0 0" />
    <parent link="base_link" />
    <child link="computer" />
    <calibration reference_position="0.0"/>
  </joint>

  <joint name="segway_laser_bracket_joint" type="fixed">    
    <origin xyz="-0.213 -0.2 0.002" rpy="0 0 0" />
    <parent link="base_link" />
    <child link="segway_laser_bracket" />
    <calibration reference_position="0.0"/>
  </joint>

  <joint name="R283_hokuyo_laser1_joint" type="revolute">    
    <origin xyz="-0.162 -0.062 0" rpy="0 0 0" />
    <axis xyz="0 0 1"/>
    <limit lower="-1.047" upper="1.047" effort="50" velocity="50"/>
    <parent link="segway_laser_bracket" />
    <child link="R283_hokuyo_laser1" />
    <calibration reference_position="0.0"/>
  </joint>

  <joint name="R313_hokuyo_laser2_joint" type="revolute">    
    <origin xyz="-0.162 0.103 0" rpy="0 0 0" />
    <axis xyz="0 0 1"/>
    <limit lower="-1.047" upper="1.047" effort="50" velocity="50"/>
    <parent link="segway_laser_bracket" />
    <child link="R313_hokuyo_laser2" />
    <calibration reference_position="0.0"/>
  </joint>

  <!-- Gazebo uses this to color -->
  <gazebo reference="base_link">
    <material value="Gazebo/Blue"/>
    <turnGravityOff>false</turnGravityOff>
  </gazebo>

  <gazebo reference="segway_left_wheel">
    <material value="Gazebo/Red"/>
    <turnGravityOff>false</turnGravityOff>
  </gazebo>

  <gazebo reference="segway_right_wheel">
    <material value="Gazebo/Red"/>
    <turnGravityOff>false</turnGravityOff>
  </gazebo>

  <gazebo reference="segway_trailer">
    <material value="Gazebo/Green"/>
    <turnGravityOff>false</turnGravityOff>
  </gazebo>

  <gazebo reference="segway_trailer_wheel_caster">
    <material value="Gazebo/Blue"/>
    <turnGravityOff>false</turnGravityOff>
  </gazebo>

  <gazebo reference="segway_trailer_wheel">
    <material value="Gazebo/Red"/>
    <turnGravityOff>false</turnGravityOff>
  </gazebo>

  <gazebo reference="battery_one">
    <material value="Gazebo/Red"/>
    <turnGravityOff>false</turnGravityOff>
  </gazebo>

  <gazebo reference="battery_two">
    <material value="Gazebo/Red"/>
    <turnGravityOff>false</turnGravityOff>
  </gazebo>

  <gazebo reference="computer">
    <material value="Gazebo/Green"/>
    <turnGravityOff>false</turnGravityOff>
  </gazebo>

  <gazebo reference="segway_laser_bracket">
    <material value="Gazebo/Green"/>
    <turnGravityOff>false</turnGravityOff>
  </gazebo>

  <gazebo reference="R283_hokuyo_laser1">
    <material value="Gazebo/Red"/>
    <turnGravityOff>false</turnGravityOff>
  </gazebo>

  <gazebo reference="R313_hokuyo_laser2">
    <material value="Gazebo/Red"/>
    <turnGravityOff>false</turnGravityOff>
  </gazebo>

  <!-- Transmits the joints -->
  <transmission name="segway_left_wheel_trans" type="SimpleTransmission">
    <actuator name="segway_left_wheel_motor"/>
    <joint name="segway_left_wheel_joint"/>
    <mechanicalReduction>1.0</mechanicalReduction>
  </transmission>

  <transmission name="segway_right_wheel_trans" type="SimpleTransmission">
    <actuator name="segway_right_wheel_motor"/>
    <joint name="segway_right_wheel_joint"/>
    <mechanicalReduction>1.0</mechanicalReduction>
  </transmission>

  <transmission name="segway_trailer_wheel_caster_trans" type="SimpleTransmission">
    <actuator name="segway_trailer_wheel_caster_motor"/>
    <joint name="segway_trailer_wheel_caster_joint"/>
    <mechanicalReduction>1.0</mechanicalReduction>
  </transmission>

  <transmission name="segway_trailer_wheel_trans" type="SimpleTransmission">
    <actuator name="segway_trailer_wheel_motor"/>
    <joint name="segway_trailer_wheel_joint"/>
    <mechanicalReduction>1.0</mechanicalReduction>
  </transmission>

  <transmission name="R283_hokuyo_laser1_trans" type="SimpleTransmission">
    <actuator name="R283_hokuyo_laser1_motor"/>
    <joint name="R283_hokuyo_laser1_joint"/>
    <mechanicalReduction>1.0</mechanicalReduction>
  </transmission>

  <transmission name="R313_hokuyo_laser2_trans" type="SimpleTransmission">
    <actuator name="R313_hokuyo_laser2_motor"/>
    <joint name="R313_hokuyo_laser2_joint"/>
    <mechanicalReduction>1.0</mechanicalReduction>
  </transmission>

  <gazebo>
    <controller:gazebo_ros_controller_manager name="gazebo_ros_controller_manager" plugin="libgazebo_ros_controller_manager.so">
      <alwaysOn>true</alwaysOn>
      <updateRate>1000.0</updateRate>
      <interface:audio name="gazebo_ros_controller_manager_dummy_iface" />
    </controller:gazebo_ros_controller_manager>
  </gazebo>

  <!-- Arm -->
  <!-- Links -->
  <link name="arm_base">
    <inertial>
        <origin xyz="0 0.08 -0.04" rpy="0 0 0" />
        <mass value="10"/>
        <inertia ixx="0.129"  ixy="0"  ixz="0" iyy="0.173" iyz="0" izz="0.087" />
    </inertial>

    <visual>
        <origin xyz="0 0 0" rpy="0 0 0" />
        <geometry name="arm_base-geom">
          <mesh filename="package://segway_robot/meshes/arm_base.stl" />
        </geometry>
        <material name="Green" />
    </visual>

    <collision>
      <origin xyz="0 0 0" rpy="0 0 0" />
      <geometry name="arm_base_collision_geom">
      <mesh filename="package://segway_robot/meshes/convex/arm_base_convex.stlb" />
      </geometry>
    </collision>

  </link>

  <link name="shoulder_pan">
    <inertial>
        <origin xyz="0 -0.048 0" rpy="0 0 0" />
        <mass value="8.394"/>
        <inertia ixx="0.138"  ixy="0"  ixz="0" iyy="0.14" iyz="0" izz="0.108" />
    </inertial>

    <visual>
        <origin xyz="0 0 0" rpy="0 0 0" />
        <geometry name="shoulder_pan-geom">
          <mesh filename="package://segway_robot/meshes/shoulder_pan.stl" />
        </geometry>
        <material name="Red" />
    </visual>

    <collision>
      <origin xyz="0 0 0" rpy="0 0 0" />
      <geometry name="shoulder_pan_collision_geom">
      <mesh filename="package://segway_robot/meshes/convex/shoulder_pan_convex.stlb" />
      </geometry>
    </collision>

  </link>

  <link name="shoulder_pitch">
    <inertial>
        <origin xyz="0 0.023 0" rpy="0 0 0" />
        <mass value="4.849"/>
        <inertia ixx="0.018"  ixy="0"  ixz="0" iyy="0.012" iyz="0" izz="0.018" />
    </inertial>

    <visual>
        <origin xyz="0 0 0" rpy="0 0 0" />
        <geometry name="shoulder_pitch-geom">
          <mesh filename="package://segway_robot/meshes/shoulder_pitch.stl" />
        </geometry>
        <material name="Blue" />
    </visual>

    <collision>
      <origin xyz="0 0 0" rpy="0 0 0" />
      <geometry name="shoulder_pitch_collision_geom">
      <mesh filename="package://segway_robot/meshes/convex/shoulder_pitch_convex.stlb" />
      </geometry>
    </collision>

  </link>

  <link name="upper_arm_roll">
    <inertial>
        <origin xyz="0 0.295 -0.02" rpy="0 0 0" />
        <mass value="1.725"/>
        <inertia ixx="0.051"  ixy="0"  ixz="0" iyy="0.002" iyz="0" izz="0.051" />
    </inertial>

    <visual>
        <origin xyz="0 0 0" rpy="0 0 0" />
        <geometry name="upper_arm_roll-geom">
          <mesh filename="package://segway_robot/meshes/upper_arm_roll.stl" />
        </geometry>
        <material name="Green" />
    </visual>

    <collision>
      <origin xyz="0 0 0" rpy="0 0 0" />
      <geometry name="upper_arm_roll_collision_geom">
      <mesh filename="package://segway_robot/meshes/convex/upper_arm_roll_convex.stlb" />
      </geometry>
    </collision>

  </link>

  <link name="elbow_lift">
    <inertial>
        <origin xyz="0 0.018 0.013" rpy="0 0 0" />
        <mass value="0.481"/>
        <inertia ixx="0.001"  ixy="0"  ixz="0" iyy="0.001" iyz="0" izz="0.001" />
    </inertial>

    <visual>
        <origin xyz="0 0 0" rpy="0 0 0" />
        <geometry name="elbow_lift-geom">
          <mesh filename="package://segway_robot/meshes/elbow_lift.stl" />
        </geometry>
        <material name="Red" />
    </visual>

    <collision>
      <origin xyz="0 0 0" rpy="0 0 0" />
      <geometry name="elbow_lift_collision_geom">
      <mesh filename="package://segway_robot/meshes/convex/elbow_lift_convex.stlb" />
      </geometry>
    </collision>

  </link>

  <link name="forearm_roll">
    <inertial>
        <origin xyz="0 0.100 0" rpy="0 0 0" />
        <mass value="1.602"/>
        <inertia ixx="0.007"  ixy="0"  ixz="0" iyy="0.003" iyz="0" izz="0.007" />
    </inertial>

    <visual>
        <origin xyz="0 0 0" rpy="0 0 0" />
        <geometry name="forearm_roll-geom">
          <mesh filename="package://segway_robot/meshes/forearm_roll.stl" />
        </geometry>
        <material name="Blue" />
    </visual>

    <collision>
      <origin xyz="0 0 0" rpy="0 0 0" />
      <geometry name="forearm_roll_collision_geom">
      <mesh filename="package://segway_robot/meshes/convex/forearm_roll_convex.stlb" />
      </geometry>
    </collision>

  </link>

  <link name="wrist_roll">
    <inertial>
        <origin xyz="0 -0.002 0" rpy="0 0 0" />
        <mass value="1.18"/>
        <inertia ixx="0.001"  ixy="0"  ixz="0" iyy="0.001" iyz="0" izz="0.001" />
    </inertial>

    <visual>
        <origin xyz="0 0 0" rpy="0 0 0" />
        <geometry name="wrist_roll-geom">
          <mesh filename="package://segway_robot/meshes/wrist_roll.stl" />
        </geometry>
        <material name="Green" />
    </visual>

    <collision>
      <origin xyz="0 0 0" rpy="0 0 0" />
      <geometry name="wrist_roll_collision_geom">
      <mesh filename="package://segway_robot/meshes/convex/wrist_roll_convex.stlb" />
      </geometry>
    </collision>

  </link>

  <link name="wrist_pitch">
    <inertial>
        <origin xyz="-0.007 0.018 0" rpy="0 0 0" />
        <mass value="0.307"/>
        <inertia ixx="0.0004"  ixy="0"  ixz="0" iyy="0.0005" iyz="0" izz="0.0005" />
    </inertial>

    <visual>
        <origin xyz="0 0 0" rpy="0 0 0" />
        <geometry name="wrist_pitch-geom">
          <mesh filename="package://segway_robot/meshes/wrist_pitch.stl" />
        </geometry>
        <material name="Red" />
    </visual>

    <collision>
      <origin xyz="0 0 0" rpy="0 0 0" />
      <geometry name="wrist_pitch_collision_geom">
      <mesh filename="package://segway_robot/meshes/convex/wrist_pitch_convex.stlb" />
      </geometry>
    </collision>

  </link>

  <!-- Joints -->
  <joint name="arm_base_joint" type="fixed">
    <origin xyz="-0.088 0.14 0.005" rpy="0 -1.57 0" />
    <child link="arm_base" />
    <parent link="base_link"/>
  </joint>

  <joint name="shoulder_pan_joint" type="revolute">
    <origin xyz="0 0.346 0" rpy="0 1.57 0" />
    <axis xyz="0 1 0"/>
    <limit lower="-2.6" upper="2.6" effort="50" velocity="50"/>
    <child link="shoulder_pan" />
    <parent link="arm_base"/>
  </joint>

  <joint name="shoulder_pitch_joint" type="revolute">
    <origin xyz="0 0 0" rpy="0 1.57 0" />
    <axis xyz="1 0 0"/>
    <limit lower="-2" upper="2" effort="50" velocity="50"/>
    <child link="shoulder_pitch" />
    <parent link="shoulder_pan"/>
  </joint>

  <joint name="upper_arm_roll_joint" type="revolute">
    <origin xyz="0 0 0" rpy="0 0 0" />
    <axis xyz="0 1 0"/>
    <limit lower="-2.8" upper="2.8" effort="50" velocity="50"/>
    <child link="upper_arm_roll" />
    <parent link="shoulder_pitch"/>
  </joint>

  <joint name="elbow_lift_joint" type="revolute">
    <origin xyz="0 0.550 -0.045" rpy="-1.57 3.14 0 " />
    <axis xyz="1 0 0"/>
    <limit lower="-0.9" upper="3.1" effort="50" velocity="50"/>
    <child link="elbow_lift" />
    <parent link="upper_arm_roll"/>
  </joint>

  <joint name="forearm_roll_joint" type="revolute">
    <origin xyz="0 0.045 0.072" rpy="1.57 0 0" />
    <axis xyz="0 1 0"/>
    <limit lower="-4.8" upper="1.3" effort="50" velocity="50"/>
    <child link="forearm_roll" />
    <parent link="elbow_lift"/>
  </joint>

  <joint name="wrist_roll_joint" type="revolute">
    <origin xyz="0 0.227 0" rpy="0 0 0" />
    <axis xyz="0 1 0"/>
    <limit lower="-2.2" upper="2.2" effort="50" velocity="50"/>
    <child link="wrist_roll" />
    <parent link="forearm_roll"/>
  </joint>

  <joint name="wrist_pitch_joint" type="revolute">
    <origin xyz="0 0 0" rpy="0 0 0" />
    <axis xyz="1 0 0"/>
    <limit lower="-1.6" upper="1.6" effort="50" velocity="50"/>
    <child link="wrist_pitch" />
    <parent link="wrist_roll"/>
  </joint>

  <!-- Gazebo data -->
  <gazebo reference="arm_base">
    <material value="Gazebo/Green"/>
    <turnGravityOff>false</turnGravityOff>
  </gazebo>

  <gazebo reference="shoulder_pan">
    <material value="Gazebo/Red"/>
    <turnGravityOff>false</turnGravityOff>
  </gazebo>

  <gazebo reference="shoulder_pitch">
    <material value="Gazebo/Blue"/>
    <turnGravityOff>false</turnGravityOff>
  </gazebo>

  <gazebo reference="upper_arm_roll">
    <material value="Gazebo/Green"/>
    <turnGravityOff>false</turnGravityOff>
  </gazebo>

  <gazebo reference="elbow_lift">
    <material value="Gazebo/Red"/>
    <turnGravityOff>false</turnGravityOff>
  </gazebo>

  <gazebo reference="forearm_roll">
    <material value="Gazebo/Blue"/>
    <turnGravityOff>false</turnGravityOff>
  </gazebo>

  <gazebo reference="wrist_roll">
    <material value="Gazebo/Green"/>
    <turnGravityOff>false</turnGravityOff>
  </gazebo>

  <gazebo reference="wrist_pitch">
    <material value="Gazebo/Red"/>
    <turnGravityOff>false</turnGravityOff>
  </gazebo>

  <!-- Transmits the joints -->
  <transmission name="shoulder_pan_joint_trans" type="SimpleTransmission">
    <actuator name="shoulder_pan_joint_motor"/>
    <joint name="shoulder_pan_joint"/>
    <mechanicalReduction>1.0</mechanicalReduction>
  </transmission>

  <transmission name="shoulder_pitch_joint_trans" type="SimpleTransmission">
    <actuator name="shoulder_pitch_joint_motor"/>
    <joint name="shoulder_pitch_joint"/>
    <mechanicalReduction>1.0</mechanicalReduction>
  </transmission>

  <transmission name="upper_arm_roll_joint_trans" type="SimpleTransmission">
    <actuator name="upper_arm_roll_joint_motor"/>
    <joint name="upper_arm_roll_joint"/>
    <mechanicalReduction>1.0</mechanicalReduction>
  </transmission>

  <transmission name="elbow_lift_joint_trans" type="SimpleTransmission">
    <actuator name="elbow_lift_joint_motor"/>
    <joint name="elbow_lift_joint"/>
    <mechanicalReduction>1.0</mechanicalReduction>
  </transmission>

  <transmission name="forearm_roll_joint_trans" type="SimpleTransmission">
    <actuator name="forearm_roll_joint_motor"/>
    <joint name="forearm_roll_joint"/>
    <mechanicalReduction>1.0</mechanicalReduction>
  </transmission>

  <transmission name="wrist_roll_joint_trans" type="SimpleTransmission">
    <actuator name="wrist_roll_joint_motor"/>
    <joint name="wrist_roll_joint"/>
    <mechanicalReduction>1.0</mechanicalReduction>
  </transmission>

  <transmission name="wrist_pitch_joint_trans" type="SimpleTransmission">
    <actuator name="wrist_pitch_joint_motor"/>
    <joint name="wrist_pitch_joint"/>
    <mechanicalReduction>1.0</mechanicalReduction>
  </transmission>

  <!-- Hand -->
  <!-- Links -->
  <link name="hand_base">
    <inertial>
        <origin xyz="0 0.0 0.0" rpy="0 0 0" />
        <mass value="0.35"/>
        <inertia ixx="1"  ixy="0"  ixz="0" iyy="1" iyz="0" izz="1" />
    </inertial>

    <visual>
        <origin xyz="0 0 0" rpy="0 0 0" />
        <geometry name="hand_base-geom">
          <mesh filename="package://segway_robot/meshes/hand_base.stl" />
        </geometry>
        <material name="White" />
    </visual>

    <collision>
      <origin xyz="0 0 0" rpy="0 0 0" />
      <geometry name="arm_base_collision_geom">
      <mesh filename="package://segway_robot/meshes/convex/hand_base_convex.stlb" />
      </geometry>
    </collision>

  </link>

  <link name="spreader_f1">
    <inertial>
        <origin xyz="0 0 0" rpy="0 0 0" />
        <mass value="0.05"/>
        <inertia ixx="1"  ixy="0"  ixz="0" iyy="1" iyz="0" izz="1" />
    </inertial>

    <visual>
        <origin xyz="0 0 0" rpy="0 0 0" />
        <geometry name="hand_base-geom">
          <mesh filename="package://segway_robot/meshes/spread_joint.stl" />
        </geometry>
        <material name="Blue" />
    </visual>

    <collision>
      <origin xyz="0 0 0" rpy="0 0 0" />
      <geometry name="arm_base_collision_geom">
      <mesh filename="package://segway_robot/meshes/convex/spread_joint_convex.stlb" />
      </geometry>
    </collision>

  </link>

  <link name="spreader_f2">
    <inertial>
        <origin xyz="0 0 0" rpy="0 0 0" />
        <mass value="0.05"/>
        <inertia ixx="1"  ixy="0"  ixz="0" iyy="1" iyz="0" izz="1" />
    </inertial>

    <visual>
        <origin xyz="0 0 0" rpy="0 0 0" />
        <geometry name="hand_base-geom">
          <mesh filename="package://segway_robot/meshes/spread_joint.stl" />
        </geometry>
        <material name="Blue" />
    </visual>

    <collision>
      <origin xyz="0 0 0" rpy="0 0 0" />
      <geometry name="arm_base_collision_geom">
      <mesh filename="package://segway_robot/meshes/convex/spread_joint_convex.stlb" />
      </geometry>
    </collision>

  </link>

  <link name="proximal_knuckle_f1">
    <inertial>
        <origin xyz="0 0 0" rpy="0 0 0" />
        <mass value="0.05"/>
        <inertia ixx="1"  ixy="0"  ixz="0" iyy="1" iyz="0" izz="1" />
    </inertial>

    <visual>
        <origin xyz="0 0 0" rpy="0 0 0" />
        <geometry name="hand_base-geom">
          <mesh filename="package://segway_robot/meshes/proximal_knuckle.stl" />
        </geometry>
        <material name="Blue" />
    </visual>

    <collision>
      <origin xyz="0 0 0" rpy="0 0 0" />
      <geometry name="arm_base_collision_geom">
      <mesh filename="package://segway_robot/meshes/convex/proximal_knuckle_convex.stlb" />
      </geometry>
    </collision>

  </link>

  <link name="proximal_knuckle_f2">
    <inertial>
        <origin xyz="0 0 0" rpy="0 0 0" />
        <mass value="0.05"/>
        <inertia ixx="1"  ixy="0"  ixz="0" iyy="1" iyz="0" izz="1" />
    </inertial>

    <visual>
        <origin xyz="0 0 0" rpy="0 0 0" />
        <geometry name="hand_base-geom">
          <mesh filename="package://segway_robot/meshes/proximal_knuckle.stl" />
        </geometry>
        <material name="Blue" />
    </visual>

    <collision>
      <origin xyz="0 0 0" rpy="0 0 0" />
      <geometry name="arm_base_collision_geom">
      <mesh filename="package://segway_robot/meshes/convex/proximal_knuckle_convex.stlb" />
      </geometry>
    </collision>

  </link>

  <link name="proximal_knuckle_f3">
    <inertial>
        <origin xyz="0 0 0" rpy="0 0 0" />
        <mass value="0.05"/>
        <inertia ixx="1"  ixy="0"  ixz="0" iyy="1" iyz="0" izz="1" />
    </inertial>

    <visual>
        <origin xyz="0 0 0" rpy="0 0 0" />
        <geometry name="hand_base-geom">
          <mesh filename="package://segway_robot/meshes/proximal_knuckle.stl" />
        </geometry>
        <material name="Blue" />
    </visual>

    <collision>
      <origin xyz="0 0 0" rpy="0 0 0" />
      <geometry name="arm_base_collision_geom">
      <mesh filename="package://segway_robot/meshes/convex/proximal_knuckle_convex.stlb" />
      </geometry>
    </collision>

  </link>

  <link name="proximal_link_f1">
    <inertial>
        <origin xyz="0 0 0" rpy="0 0 0" />
        <mass value="0.1"/>
        <inertia ixx="1"  ixy="0"  ixz="0" iyy="1" iyz="0" izz="1" />
    </inertial>

    <visual>
        <origin xyz="0 0 0" rpy="0 0 0" />
        <geometry name="hand_base-geom">
          <mesh filename="package://segway_robot/meshes/proximal_link.stl" />
        </geometry>
        <material name="Blue" />
    </visual>

    <collision>
      <origin xyz="0 0 0" rpy="0 0 0" />
      <geometry name="arm_base_collision_geom">
      <mesh filename="package://segway_robot/meshes/convex/proximal_link_convex.stlb" />
      </geometry>
    </collision>

  </link>

  <link name="proximal_link_f2">
    <inertial>
        <origin xyz="0 0 0" rpy="0 0 0" />
        <mass value="0.1"/>
        <inertia ixx="1"  ixy="0"  ixz="0" iyy="1" iyz="0" izz="1" />
    </inertial>

    <visual>
        <origin xyz="0 0 0" rpy="0 0 0" />
        <geometry name="hand_base-geom">
          <mesh filename="package://segway_robot/meshes/proximal_link.stl" />
        </geometry>
        <material name="Blue" />
    </visual>

    <collision>
      <origin xyz="0 0 0" rpy="0 0 0" />
      <geometry name="arm_base_collision_geom">
      <mesh filename="package://segway_robot/meshes/convex/proximal_link_convex.stlb" />
      </geometry>
    </collision>

  </link>

  <link name="proximal_link_f3">
    <inertial>
        <origin xyz="0 0 0" rpy="0 0 0" />
        <mass value="0.1"/>
        <inertia ixx="1"  ixy="0"  ixz="0" iyy="1" iyz="0" izz="1" />
    </inertial>

    <visual>
        <origin xyz="0 0 0" rpy="0 0 0" />
        <geometry name="hand_base-geom">
          <mesh filename="package://segway_robot/meshes/proximal_link.stl" />
        </geometry>
        <material name="Blue" />
    </visual>

    <collision>
      <origin xyz="0 0 0" rpy="0 0 0" />
      <geometry name="arm_base_collision_geom">
      <mesh filename="package://segway_robot/meshes/convex/proximal_link_convex.stlb" />
      </geometry>
    </collision>

  </link>

  <link name="distal_knuckle_f1">
    <inertial>
        <origin xyz="0 0 0" rpy="0 0 0" />
        <mass value="0.05"/>
        <inertia ixx="1"  ixy="0"  ixz="0" iyy="1" iyz="0" izz="1" />
    </inertial>

    <visual>
        <origin xyz="0 0 0" rpy="0 0 0" />
        <geometry name="hand_base-geom">
          <mesh filename="package://segway_robot/meshes/distal_knuckle.stl" />
        </geometry>
        <material name="Blue" />
    </visual>

    <collision>
      <origin xyz="0 0 0" rpy="0 0 0" />
      <geometry name="arm_base_collision_geom">
      <mesh filename="package://segway_robot/meshes/convex/distal_knuckle_convex.stlb" />
      </geometry>
    </collision>

  </link>

  <link name="distal_knuckle_f2">
    <inertial>
        <origin xyz="0 0 0" rpy="0 0 0" />
        <mass value="0.05"/>
        <inertia ixx="1"  ixy="0"  ixz="0" iyy="1" iyz="0" izz="1" />
    </inertial>

    <visual>
        <origin xyz="0 0 0" rpy="0 0 0" />
        <geometry name="hand_base-geom">
          <mesh filename="package://segway_robot/meshes/distal_knuckle.stl" />
        </geometry>
        <material name="Blue" />
    </visual>

    <collision>
      <origin xyz="0 0 0" rpy="0 0 0" />
      <geometry name="arm_base_collision_geom">
      <mesh filename="package://segway_robot/meshes/convex/distal_knuckle_convex.stlb" />
      </geometry>
    </collision>

  </link>

  <link name="distal_knuckle_f3">
    <inertial>
        <origin xyz="0 0 0" rpy="0 0 0" />
        <mass value="0.05"/>
        <inertia ixx="1"  ixy="0"  ixz="0" iyy="1" iyz="0" izz="1" />
    </inertial>

    <visual>
        <origin xyz="0 0 0" rpy="0 0 0" />
        <geometry name="hand_base-geom">
          <mesh filename="package://segway_robot/meshes/distal_knuckle.stl" />
        </geometry>
        <material name="Blue" />
    </visual>

    <collision>
      <origin xyz="0 0 0" rpy="0 0 0" />
      <geometry name="arm_base_collision_geom">
      <mesh filename="package://segway_robot/meshes/convex/distal_knuckle_convex.stlb" />
      </geometry>
    </collision>

  </link>

  <link name="finger_tip_f1">
    <inertial>
        <origin xyz="0 0 0" rpy="0 0 0" />
        <mass value="0.05"/>
        <inertia ixx="1"  ixy="0"  ixz="0" iyy="1" iyz="0" izz="1" />
    </inertial>

    <visual>
        <origin xyz="0 0 0" rpy="0 0 0" />
        <geometry name="hand_base-geom">
          <mesh filename="package://segway_robot/meshes/finger_tip.stl" />
        </geometry>
        <material name="Blue" />
    </visual>

    <collision>
      <origin xyz="0 0 0" rpy="0 0 0" />
      <geometry name="arm_base_collision_geom">
      <mesh filename="package://segway_robot/meshes/convex/finger_tip_convex.stlb" />
      </geometry>
    </collision>

  </link>

  <link name="finger_tip_f2">
    <inertial>
        <origin xyz="0 0 0" rpy="0 0 0" />
        <mass value="0.05"/>
        <inertia ixx="1"  ixy="0"  ixz="0" iyy="1" iyz="0" izz="1" />
    </inertial>

    <visual>
        <origin xyz="0 0 0" rpy="0 0 0" />
        <geometry name="hand_base-geom">
          <mesh filename="package://segway_robot/meshes/finger_tip.stl" />
        </geometry>
        <material name="Blue" />
    </visual>

    <collision>
      <origin xyz="0 0 0" rpy="0 0 0" />
      <geometry name="arm_base_collision_geom">
      <mesh filename="package://segway_robot/meshes/convex/finger_tip_convex.stlb" />
      </geometry>
    </collision>

  </link>

  <link name="finger_tip_f3">
    <inertial>
        <origin xyz="0 0 0" rpy="0 0 0" />
        <mass value="0.05"/>
        <inertia ixx="1"  ixy="0"  ixz="0" iyy="1" iyz="0" izz="1" />
    </inertial>

    <visual>
        <origin xyz="0 0 0" rpy="0 0 0" />
        <geometry name="hand_base-geom">
          <mesh filename="package://segway_robot/meshes/finger_tip.stl" />
        </geometry>
        <material name="Blue" />
    </visual>

    <collision>
      <origin xyz="0 0 0" rpy="0 0 0" />
      <geometry name="arm_base_collision_geom">
      <mesh filename="package://segway_robot/meshes/convex/finger_tip_convex.stlb" />
      </geometry>
    </collision>

  </link>

  <!-- Joints -->
  <joint name="hand_base_joint" type="fixed">
    <origin xyz="0 0.116 0" rpy="0 0 0" />
    <child link="hand_base" />
    <parent link="wrist_pitch"/>
  </joint>

  <joint name="spreader_joint_f1" type="revolute">
    <origin xyz="0.031 0.003 0" rpy="0 0 0" />
    <axis xyz="0 1 0"/>
    <limit lower="0" upper="3.14" effort="50" velocity="50"/>
    <child link="spreader_f1" />
    <parent link="hand_base"/>
  </joint>

  <joint name="spreader_joint_f2" type="revolute">
    <origin xyz="-0.031 0.003 0" rpy="0 0 0" />
    <axis xyz="0 1 0"/>
    <limit lower="-3.14" upper="0" effort="50" velocity="50"/>
    <child link="spreader_f2" />
    <parent link="hand_base"/>
  </joint>

  <joint name="proximal_knuckle_joint_f1" type="fixed">
    <origin xyz="0 0.034 0.05" rpy="0 3.14 0" />
    <child link="proximal_knuckle_f1" />
    <parent link="spreader_f1"/>
  </joint>

  <joint name="proximal_knuckle_joint_f2" type="fixed">
    <origin xyz="0 0.034 0.05" rpy="0 3.14 0" />
    <child link="proximal_knuckle_f2" />
    <parent link="spreader_f2"/>
  </joint>

  <joint name="proximal_knuckle_joint_f3" type="fixed">
    <origin xyz="0 0.037 -0.05" rpy="0 0 0" />
    <child link="proximal_knuckle_f3" />
    <parent link="hand_base"/>
  </joint>

  <joint name="proximal_link_joint_f1" type="revolute">
    <origin xyz="0 0 0" rpy="-1.57 0 0" />
    <axis xyz="1 0 0"/>
    <limit lower="-1.57" upper="0.873" effort="50" velocity="50"/>
    <child link="proximal_link_f1" />
    <parent link="proximal_knuckle_f1"/>
  </joint>

  <joint name="proximal_link_joint_f2" type="revolute">
    <origin xyz="0 0 0" rpy="-1.57 0 0" />
    <axis xyz="1 0 0"/>
    <limit lower="-1.57" upper="0.873" effort="50" velocity="50"/>
    <child link="proximal_link_f2" />
    <parent link="proximal_knuckle_f2"/>
  </joint>

  <joint name="proximal_link_joint_f3" type="revolute">
    <origin xyz="0 0 0" rpy="-1.57 0 0" />
    <axis xyz="1 0 0"/>
    <limit lower="-1.57" upper="0.873" effort="50" velocity="50"/>
    <child link="proximal_link_f3" />
    <parent link="proximal_knuckle_f3"/>
  </joint>

  <joint name="distal_knuckle_joint_f1" type="revolute">
    <origin xyz="0 0 0.071" rpy="1.57 0 0" />
    <axis xyz="1 0 0"/>
    <limit lower="-0.785" upper="0" effort="50" velocity="50"/>
    <child link="distal_knuckle_f1" />
    <parent link="proximal_link_f1"/>
  </joint>

  <joint name="distal_knuckle_joint_f2" type="revolute">
    <origin xyz="0 0 0.071" rpy="1.57 0 0" />
    <axis xyz="1 0 0"/>
    <limit lower="-0.785" upper="0" effort="50" velocity="50"/>
    <child link="distal_knuckle_f2" />
    <parent link="proximal_link_f2"/>
  </joint>

  <joint name="distal_knuckle_joint_f3" type="revolute">
    <origin xyz="0 0 0.071" rpy="1.57 0 0" />
    <axis xyz="1 0 0"/>
    <limit lower="-0.785" upper="0" effort="50" velocity="50"/>
    <child link="distal_knuckle_f3" />
    <parent link="proximal_link_f3"/>
  </joint>

  <joint name="finger_tip_joint_f1" type="fixed">
    <origin xyz="0 -0.009 0.01" rpy="-1.57 3.14 0" />
    <child link="finger_tip_f1" />
    <parent link="distal_knuckle_f1"/>
  </joint>

  <joint name="finger_tip_joint_f2" type="fixed">
    <origin xyz="0 -0.009 0.01" rpy="-1.57 3.14 0" />
    <child link="finger_tip_f2" />
    <parent link="distal_knuckle_f2"/>
  </joint>

  <joint name="finger_tip_joint_f3" type="fixed">
    <origin xyz="0 -0.009 0.01" rpy="-1.57 3.14 0" />
    <child link="finger_tip_f3" />
    <parent link="distal_knuckle_f3"/>
  </joint>

  <!-- Gazebo data -->
  <gazebo reference="hand_base">
    <material value="Gazebo/White"/>
    <turnGravityOff>false</turnGravityOff>
  </gazebo>

  <gazebo reference="spreader_f1">
    <material value="Gazebo/Blue"/>
    <turnGravityOff>false</turnGravityOff>
  </gazebo>

  <gazebo reference="spreader_f2">
    <material value="Gazebo/Blue"/>
    <turnGravityOff>false</turnGravityOff>
  </gazebo>

  <gazebo reference="proximal_knuckle_f1">
    <material value="Gazebo/Red"/>
    <turnGravityOff>false</turnGravityOff>
  </gazebo>

  <gazebo reference="proximal_knuckle_f2">
    <material value="Gazebo/Red"/>
    <turnGravityOff>false</turnGravityOff>
  </gazebo>

  <gazebo reference="proximal_knuckle_f3">
    <material value="Gazebo/Red"/>
    <turnGravityOff>false</turnGravityOff>
  </gazebo>

  <gazebo reference="proximal_link_f1">
    <material value="Gazebo/Blue"/>
    <turnGravityOff>false</turnGravityOff>
  </gazebo>

  <gazebo reference="proximal_link_f2">
    <material value="Gazebo/Blue"/>
    <turnGravityOff>false</turnGravityOff>
  </gazebo>

  <gazebo reference="proximal_link_f3">
    <material value="Gazebo/Blue"/>
    <turnGravityOff>false</turnGravityOff>
  </gazebo>

  <gazebo reference="distal_knuckle_f1">
    <material value="Gazebo/White"/>
    <turnGravityOff>false</turnGravityOff>
  </gazebo>

  <gazebo reference="distal_knuckle_f2">
    <material value="Gazebo/White"/>
    <turnGravityOff>false</turnGravityOff>
  </gazebo>

  <gazebo reference="distal_knuckle_f3">
    <material value="Gazebo/White"/>
    <turnGravityOff>false</turnGravityOff>
  </gazebo>

  <gazebo reference="finger_tip_f1">
    <material value="Gazebo/Red"/>
    <turnGravityOff>false</turnGravityOff>
  </gazebo>

  <gazebo reference="finger_tip_f2">
    <material value="Gazebo/Red"/>
    <turnGravityOff>false</turnGravityOff>
  </gazebo>

  <gazebo reference="finger_tip_f3">
    <material value="Gazebo/Red"/>
    <turnGravityOff>false</turnGravityOff>
  </gazebo>

  <!-- Transmits the joints -->
  <transmission name="spreader_joint_f1_trans" type="SimpleTransmission">
    <actuator name="spreader_joint_f1_motor"/>
    <joint name="spreader_joint_f1"/>
    <mechanicalReduction>1.0</mechanicalReduction>
  </transmission>

  <transmission name="spreader_joint_f2_trans" type="SimpleTransmission">
    <actuator name="spreader_joint_f2_motor"/>
    <joint name="spreader_joint_f2"/>
    <mechanicalReduction>1.0</mechanicalReduction>
  </transmission>

  <transmission name="proximal_link_joint_f1_trans" type="SimpleTransmission">
    <actuator name="proximal_link_joint_f1_motor"/>
    <joint name="proximal_link_joint_f1"/>
    <mechanicalReduction>1.0</mechanicalReduction>
  </transmission>

  <transmission name="proximal_link_joint_f2_trans" type="SimpleTransmission">
    <actuator name="proximal_link_joint_f2_motor"/>
    <joint name="proximal_link_joint_f2"/>
    <mechanicalReduction>1.0</mechanicalReduction>
  </transmission>

  <transmission name="proximal_link_joint_f3_trans" type="SimpleTransmission">
    <actuator name="proximal_link_joint_f3_motor"/>
    <joint name="proximal_link_joint_f3"/>
    <mechanicalReduction>1.0</mechanicalReduction>
  </transmission>

  <transmission name="distal_knuckle_joint_f1_trans" type="SimpleTransmission">
    <actuator name="distal_knuckle_joint_f1_motor"/>
    <joint name="distal_knuckle_joint_f1"/>
    <mechanicalReduction>1.0</mechanicalReduction>
  </transmission>

  <transmission name="distal_knuckle_joint_f2_trans" type="SimpleTransmission">
    <actuator name="distal_knuckle_joint_f2_motor"/>
    <joint name="distal_knuckle_joint_f2"/>
    <mechanicalReduction>1.0</mechanicalReduction>
  </transmission>

  <transmission name="distal_knuckle_joint_f3_trans" type="SimpleTransmission">
    <actuator name="distal_knuckle_joint_f3_motor"/>
    <joint name="distal_knuckle_joint_f3"/>
    <mechanicalReduction>1.0</mechanicalReduction>
  </transmission>

  <!-- Laser base laser -->
  <!-- Joint to world. Simply change the name and parent link when attaching to own robot -->
  <joint name="base_laser_joint" type="fixed">
      <origin xyz="-0.057 0.010 0" rpy="-1.57 0 3.14" />
      <parent link="R283_hokuyo_laser1"/>
      <child link="base_laser_link"/>
    </joint>

  <!--			 Laser body. Neglegibe geometry 			-->
  <link name="base_laser_link" type="laser">

      <inertial>
        <mass value="0.000001" />
        <origin xyz="0 0 0" rpy="0 0 0" />
        <inertia ixx="0.0001" ixy="0" ixz="0" iyy="0.000001" iyz="0" izz="0.0001" />
      </inertial>
      <visual>
        <origin xyz="0 0 0" rpy="0 0 0" />
        <geometry>
          <box size="0.000 0.000 0.000" />
        </geometry>
        <material name="Red" />
      </visual>
      <collision>
        <origin xyz="0 0 0" rpy="0 0 0" />
        <geometry>
          <box size=".000 .000 .00" />
        </geometry>
      </collision>

    </link>

<!-- 			Actual laser		 -->
    <gazebo reference="base_laser_link">    
      <sensor:ray name="base_laser">
        <rayCount>1080</rayCount>
        <rangeCount>1080</rangeCount>
        <laserCount>1</laserCount>

        <origin>0.0 0.0 0.0</origin>
        <displayRays>false</displayRays>

        <minAngle>-120</minAngle>
        <maxAngle> 119</maxAngle>

        <minRange>0.05</minRange>
        <maxRange>10.0</maxRange>
        <resRange>0.01</resRange>
        <updateRate>20.0</updateRate>

        <controller:gazebo_ros_laser name="gazebo_ros_base_laser_controller" plugin="libgazebo_ros_laser.so">
          <gaussianNoise>0.005</gaussianNoise>
          <alwaysOn>true</alwaysOn>
          <updateRate>20.0</updateRate>
          <topicName>scan</topicName>
          <frameName>base_laser_link</frameName>
          <interface:laser name="gazebo_ros_base_laser_iface"/>
        </controller:gazebo_ros_laser>
      </sensor:ray>
    </gazebo>

  <!-- Laser tilt laser -->
  <!-- Joint to world. Simply change the name and parent link when attaching to own robot -->
  <joint name="tilt_laser_joint" type="fixed">
      <origin xyz="-0.056 0.020 0" rpy="-1.57 0 3.14" />
      <parent link="R313_hokuyo_laser2"/>
      <child link="tilt_laser_link"/>
    </joint>

  <!--			 Laser body. Neglegibe geometry 			-->
  <link name="tilt_laser_link" type="laser">

      <inertial>
        <mass value="0.000001" />
        <origin xyz="0 0 0" rpy="0 0 0" />
        <inertia ixx="0.0001" ixy="0" ixz="0" iyy="0.000001" iyz="0" izz="0.0001" />
      </inertial>
      <visual>
        <origin xyz="0 0 0" rpy="0 0 0" />
        <geometry>
          <box size="0 0 0" />
        </geometry>
        <material name="Red" />
      </visual>
      <collision>
        <origin xyz="0 0 0" rpy="0 0 0" />
        <geometry>
          <box size="0 0 0" />
        </geometry>
      </collision>

    </link>

<!-- 			Actual laser		 -->
<gazebo reference="tilt_laser_link">    
      <sensor:ray name="tilt_laser">
        <rayCount>1080</rayCount>
        <rangeCount>1080</rangeCount>
        <laserCount>1</laserCount>

        <origin>0.0 0.0 0.0</origin>
        <displayRays>false</displayRays>

        <minAngle>-130</minAngle>
        <maxAngle> 130</maxAngle>

        <minRange>0.05</minRange>
        <maxRange>10.0</maxRange>
        <resRange>0.01</resRange>
        <updateRate>20.0</updateRate>

        <controller:gazebo_ros_laser name="gazebo_ros_tilt_laser_controller" plugin="libgazebo_ros_laser.so">
          <gaussianNoise>0.005</gaussianNoise>
          <alwaysOn>true</alwaysOn>
          <updateRate>20.0</updateRate>
          <topicName>tilt_scan</topicName>
          <frameName>tilt_laser_link</frameName>
          <interface:laser name="gazebo_ros_tilt_laser_iface"/>
        </controller:gazebo_ros_laser>
      </sensor:ray>
</gazebo>

<gazebo>
  <controller:gazebo_ros_p3d name="p3d_base_controller" plugin="libgazebo_ros_p3d.so">
    <alwaysOn>true</alwaysOn>
    <updateRate>100.0</updateRate>
    <bodyName>base_footprint</bodyName>
    <topicName>base_pose_ground_truth</topicName>
    <gaussianNoise>0.01</gaussianNoise>
    <frameName>map</frameName>
    <xyzOffsets>25.7 25.7 0</xyzOffsets> <!-- initialize odometry for fake localization-->
    <rpyOffsets>0 0 0</rpyOffsets>
    <interface:position name="p3d_base_position"/>
  </controller:gazebo_ros_p3d>
  <canonicalBody>base_footprint</canonicalBody>
</gazebo>


</robot>
