<?xml version="1.0"?>
<robot name="arm"
       xmlns:sensor="http://playerstage.sourceforge.net/gazebo/xmlschema/#sensor" 
       xmlns:controller="http://playerstage.sourceforge.net/gazebo/xmlschema/#controller"
       xmlns:xacro="http://ros.org/wiki/fixme"
       xmlns:interface="http://playerstage.sourceforge.net/gazebo/xmlschema/#interface">>  

<!-- JOINT LIMIT VALUES FOR EFFORT AND VELOCITY NEED TO BE ADDED FOR REVOLUTE AND CONTINUOUS JOINTS -->


  <!-- Arm -->

  <!-- Links -->
  <link name="arm_base">
    <inertial>
        <origin xyz="0 0.08 -0.04" rpy="0 0 0" />
        <mass value="10"/>
        <inertia ixx="0.129"  ixy="0"  ixz="0" iyy="0.173" iyz="0" izz="0.087" />
    </inertial>

    <visual>
        <origin xyz="0 0 0" rpy="0 0 0" />
        <geometry name="arm_base-geom">
          <mesh filename="package://segway_robot/meshes/arm_base.stl" />
        </geometry>
        <material name="Green" />
    </visual>

    <collision>
      <origin xyz="0 0 0" rpy="0 0 0" />
      <geometry name="arm_base_collision_geom">
      <mesh filename="package://segway_robot/meshes/convex/arm_base_convex.stlb" />
      </geometry>
    </collision>

  </link>

  <link name="shoulder_pan">
    <inertial>
        <origin xyz="0 -0.048 0" rpy="0 0 0" />
        <mass value="8.394"/>
        <inertia ixx="0.138"  ixy="0"  ixz="0" iyy="0.14" iyz="0" izz="0.108" />
    </inertial>

    <visual>
        <origin xyz="0 0 0" rpy="0 0 0" />
        <geometry name="shoulder_pan-geom">
          <mesh filename="package://segway_robot/meshes/shoulder_pan.stl" />
        </geometry>
        <material name="Red" />
    </visual>

    <collision>
      <origin xyz="0 0 0" rpy="0 0 0" />
      <geometry name="shoulder_pan_collision_geom">
      <mesh filename="package://segway_robot/meshes/convex/shoulder_pan_convex.stlb" />
      </geometry>
    </collision>

  </link>

  <link name="shoulder_pitch">
    <inertial>
        <origin xyz="0 0.023 0" rpy="0 0 0" />
        <mass value="4.849"/>
        <inertia ixx="0.018"  ixy="0"  ixz="0" iyy="0.012" iyz="0" izz="0.018" />
    </inertial>

    <visual>
        <origin xyz="0 0 0" rpy="0 0 0" />
        <geometry name="shoulder_pitch-geom">
          <mesh filename="package://segway_robot/meshes/shoulder_pitch.stl" />
        </geometry>
        <material name="Blue" />
    </visual>

    <collision>
      <origin xyz="0 0 0" rpy="0 0 0" />
      <geometry name="shoulder_pitch_collision_geom">
      <mesh filename="package://segway_robot/meshes/convex/shoulder_pitch_convex.stlb" />
      </geometry>
    </collision>

  </link>

  <link name="upper_arm_roll">
    <inertial>
        <origin xyz="0 0.295 -0.02" rpy="0 0 0" />
        <mass value="1.725"/>
        <inertia ixx="0.051"  ixy="0"  ixz="0" iyy="0.002" iyz="0" izz="0.051" />
    </inertial>

    <visual>
        <origin xyz="0 0 0" rpy="0 0 0" />
        <geometry name="upper_arm_roll-geom">
          <mesh filename="package://segway_robot/meshes/upper_arm_roll.stl" />
        </geometry>
        <material name="Green" />
    </visual>

    <collision>
      <origin xyz="0 0 0" rpy="0 0 0" />
      <geometry name="upper_arm_roll_collision_geom">
      <mesh filename="package://segway_robot/meshes/convex/upper_arm_roll_convex.stlb" />
      </geometry>
    </collision>

  </link>

  <link name="elbow_lift">
    <inertial>
        <origin xyz="0 0.018 0.013" rpy="0 0 0" />
        <mass value="0.481"/>
        <inertia ixx="0.001"  ixy="0"  ixz="0" iyy="0.001" iyz="0" izz="0.001" />
    </inertial>

    <visual>
        <origin xyz="0 0 0" rpy="0 0 0" />
        <geometry name="elbow_lift-geom">
          <mesh filename="package://segway_robot/meshes/elbow_lift.stl" />
        </geometry>
        <material name="Red" />
    </visual>

    <collision>
      <origin xyz="0 0 0" rpy="0 0 0" />
      <geometry name="elbow_lift_collision_geom">
      <mesh filename="package://segway_robot/meshes/convex/elbow_lift_convex.stlb" />
      </geometry>
    </collision>

  </link>

  <link name="forearm_roll">
    <inertial>
        <origin xyz="0 0.100 0" rpy="0 0 0" />
        <mass value="1.602"/>
        <inertia ixx="0.007"  ixy="0"  ixz="0" iyy="0.003" iyz="0" izz="0.007" />
    </inertial>

    <visual>
        <origin xyz="0 0 0" rpy="0 0 0" />
        <geometry name="forearm_roll-geom">
          <mesh filename="package://segway_robot/meshes/forearm_roll.stl" />
        </geometry>
        <material name="Blue" />
    </visual>

    <collision>
      <origin xyz="0 0 0" rpy="0 0 0" />
      <geometry name="forearm_roll_collision_geom">
      <mesh filename="package://segway_robot/meshes/convex/forearm_roll_convex.stlb" />
      </geometry>
    </collision>

  </link>

  <link name="wrist_roll">
    <inertial>
        <origin xyz="0 -0.002 0" rpy="0 0 0" />
        <mass value="1.18"/>
        <inertia ixx="0.001"  ixy="0"  ixz="0" iyy="0.001" iyz="0" izz="0.001" />
    </inertial>

    <visual>
        <origin xyz="0 0 0" rpy="0 0 0" />
        <geometry name="wrist_roll-geom">
          <mesh filename="package://segway_robot/meshes/wrist_roll.stl" />
        </geometry>
        <material name="Green" />
    </visual>

    <collision>
      <origin xyz="0 0 0" rpy="0 0 0" />
      <geometry name="wrist_roll_collision_geom">
      <mesh filename="package://segway_robot/meshes/convex/wrist_roll_convex.stlb" />
      </geometry>
    </collision>

  </link>

  <link name="wrist_pitch">
    <inertial>
        <origin xyz="-0.007 0.018 0" rpy="0 0 0" />
        <mass value="0.307"/>
        <inertia ixx="0.0004"  ixy="0"  ixz="0" iyy="0.0005" iyz="0" izz="0.0005" />
    </inertial>

    <visual>
        <origin xyz="0 0 0" rpy="0 0 0" />
        <geometry name="wrist_pitch-geom">
          <mesh filename="package://segway_robot/meshes/wrist_pitch.stl" />
        </geometry>
        <material name="Red" />
    </visual>

    <collision>
      <origin xyz="0 0 0" rpy="0 0 0" />
      <geometry name="wrist_pitch_collision_geom">
      <mesh filename="package://segway_robot/meshes/convex/wrist_pitch_convex.stlb" />
      </geometry>
    </collision>

  </link>

  <!-- Joints -->
  <joint name="arm_base_joint" type="fixed">
    <origin xyz="-0.088 0.14 0.005" rpy="0 -1.57 0" />
    <child link="arm_base" />
    <parent link="base_link"/>
  </joint>

  <joint name="shoulder_pan_joint" type="revolute">
    <origin xyz="0 0.346 0" rpy="0 1.57 0" />
    <axis xyz="0 1 0"/>
    <limit lower="-2.6" upper="2.6" effort="50" velocity="50"/>
    <child link="shoulder_pan" />
    <parent link="arm_base"/>
  </joint>

  <joint name="shoulder_pitch_joint" type="revolute">
    <origin xyz="0 0 0" rpy="0 1.57 0" />
    <axis xyz="1 0 0"/>
    <limit lower="-2" upper="2" effort="50" velocity="50"/>
    <child link="shoulder_pitch" />
    <parent link="shoulder_pan"/>
  </joint>

  <joint name="upper_arm_roll_joint" type="revolute">
    <origin xyz="0 0 0" rpy="0 0 0" />
    <axis xyz="0 1 0"/>
    <limit lower="-2.8" upper="2.8" effort="50" velocity="50"/>
    <child link="upper_arm_roll" />
    <parent link="shoulder_pitch"/>
  </joint>

  <joint name="elbow_lift_joint" type="revolute">
    <origin xyz="0 0.550 -0.045" rpy="-1.57 3.14 0 " />
    <axis xyz="1 0 0"/>
    <limit lower="-0.9" upper="3.1" effort="50" velocity="50"/>
    <child link="elbow_lift" />
    <parent link="upper_arm_roll"/>
  </joint>

  <joint name="forearm_roll_joint" type="revolute">
    <origin xyz="0 0.045 0.072" rpy="1.57 0 0" />
    <axis xyz="0 1 0"/>
    <limit lower="-4.8" upper="1.3" effort="50" velocity="50"/>
    <child link="forearm_roll" />
    <parent link="elbow_lift"/>
  </joint>

  <joint name="wrist_roll_joint" type="revolute">
    <origin xyz="0 0.227 0" rpy="0 0 0" />
    <axis xyz="0 1 0"/>
    <limit lower="-2.2" upper="2.2" effort="50" velocity="50"/>
    <child link="wrist_roll" />
    <parent link="forearm_roll"/>
  </joint>

  <joint name="wrist_pitch_joint" type="revolute">
    <origin xyz="0 0 0" rpy="0 0 0" />
    <axis xyz="1 0 0"/>
    <limit lower="-1.6" upper="1.6" effort="50" velocity="50"/>
    <child link="wrist_pitch" />
    <parent link="wrist_roll"/>
  </joint>

  <!-- Gazebo data -->
  <gazebo reference="arm_base">
    <material value="Gazebo/Green"/>
    <turnGravityOff>false</turnGravityOff>
  </gazebo>

  <gazebo reference="shoulder_pan">
    <material value="Gazebo/Red"/>
    <turnGravityOff>false</turnGravityOff>
  </gazebo>

  <gazebo reference="shoulder_pitch">
    <material value="Gazebo/Blue"/>
    <turnGravityOff>false</turnGravityOff>
  </gazebo>

  <gazebo reference="upper_arm_roll">
    <material value="Gazebo/Green"/>
    <turnGravityOff>false</turnGravityOff>
  </gazebo>

  <gazebo reference="elbow_lift">
    <material value="Gazebo/Red"/>
    <turnGravityOff>false</turnGravityOff>
  </gazebo>

  <gazebo reference="forearm_roll">
    <material value="Gazebo/Blue"/>
    <turnGravityOff>false</turnGravityOff>
  </gazebo>

  <gazebo reference="wrist_roll">
    <material value="Gazebo/Green"/>
    <turnGravityOff>false</turnGravityOff>
  </gazebo>

  <gazebo reference="wrist_pitch">
    <material value="Gazebo/Red"/>
    <turnGravityOff>false</turnGravityOff>
  </gazebo>

  <!-- Transmits the joints -->
  <transmission name="shoulder_pan_joint_trans" type="SimpleTransmission">
    <actuator name="shoulder_pan_joint_motor"/>
    <joint name="shoulder_pan_joint"/>
    <mechanicalReduction>1.0</mechanicalReduction>
  </transmission>

  <transmission name="shoulder_pitch_joint_trans" type="SimpleTransmission">
    <actuator name="shoulder_pitch_joint_motor"/>
    <joint name="shoulder_pitch_joint"/>
    <mechanicalReduction>1.0</mechanicalReduction>
  </transmission>

  <transmission name="upper_arm_roll_joint_trans" type="SimpleTransmission">
    <actuator name="upper_arm_roll_joint_motor"/>
    <joint name="upper_arm_roll_joint"/>
    <mechanicalReduction>1.0</mechanicalReduction>
  </transmission>

  <transmission name="elbow_lift_joint_trans" type="SimpleTransmission">
    <actuator name="elbow_lift_joint_motor"/>
    <joint name="elbow_lift_joint"/>
    <mechanicalReduction>1.0</mechanicalReduction>
  </transmission>

  <transmission name="forearm_roll_joint_trans" type="SimpleTransmission">
    <actuator name="forearm_roll_joint_motor"/>
    <joint name="forearm_roll_joint"/>
    <mechanicalReduction>1.0</mechanicalReduction>
  </transmission>

  <transmission name="wrist_roll_joint_trans" type="SimpleTransmission">
    <actuator name="wrist_roll_joint_motor"/>
    <joint name="wrist_roll_joint"/>
    <mechanicalReduction>1.0</mechanicalReduction>
  </transmission>

  <transmission name="wrist_pitch_joint_trans" type="SimpleTransmission">
    <actuator name="wrist_pitch_joint_motor"/>
    <joint name="wrist_pitch_joint"/>
    <mechanicalReduction>1.0</mechanicalReduction>
  </transmission>

</robot>
